<?xml version="1.0" ?>
<robot name="turtlebot3_robot" xmlns:xacro="http://ros.org/wiki/xacro">
  <xacro:include filename="$(find turtlebot3_description)/urdf/common_properties.xacro"/>
  <xacro:include filename="$(find turtlebot3_description)/urdf/turtlebot3_robot.gazebo.xacro"/>

  <link name="base_footprint"/>

  <joint
    name="base_Joint"
    type="fixed">
    <origin
      xyz="0 0 0"
      rpy="0 0 0" />
    <parent
      link="base_footprint" />
    <child
      link="base_Link" />
    <axis
      xyz="0 0 0" />
  </joint>

  <link
    name="base_Link">
    <inertial>
      <origin
        xyz="-0.030671797677721 -5.55111512312578E-17 0.0852752856857115"
        rpy="0 0 0" />
      <mass
        value="13.0937163721216" />
      <inertia
        ixx="0.109953174405713"
        ixy="4.5294574942155E-18"
        ixz="0.0269987870043487"
        iyy="0.163918210458872"
        iyz="1.33143001951345E-18"
        izz="0.190239575568999" />
    </inertial>
    <visual>
      <origin
        xyz="0 0 0"
        rpy="0 0 0" />
      <geometry>
        <mesh
          filename="package://robot/meshes/base_Link.STL" />
      </geometry>
      <material
        name="">
        <color
          rgba="0.792156862745098 0.819607843137255 0.933333333333333 1" />
      </material>
    </visual>
    <collision>
      <origin
        xyz="0 0 0"
        rpy="0 0 0" />
      <geometry>
        <mesh
          filename="package://robot/meshes/base_Link.STL" />
      </geometry>
    </collision>
  </link>

  <joint
    name="left_Joint"
    type="continuous">
    <origin
      xyz="0 0.165 0.0199999999999999"
      rpy="1.5707963267949 0 0" />
    <parent
      link="base_Link" />
    <child
      link="left_Link" />
    <axis
      xyz="0 0 -1" />
  </joint>

  <link
    name="left_Link">
    <inertial>
      <origin
        xyz="0 0 0.0200584795321638"
        rpy="0 0 0" />
      <mass
        value="0.201454628911445" />
      <inertia
        ixx="0.000107599473032008"
        ixy="6.37539871308252E-21"
        ixz="3.00122285610467E-21"
        iyy="0.000107599473032008"
        iyz="2.16884852505552E-21"
        izz="0.000160850771048428" />
    </inertial>
    <visual>
      <origin
        xyz="0 0 0"
        rpy="0 0 0" />
      <geometry>
        <mesh
          filename="package://robot/meshes/left_Link.STL" />
      </geometry>
      <material
        name="">
        <color
          rgba="0.792156862745098 0.819607843137255 0.933333333333333 1" />
      </material>
    </visual>
    <collision>
      <origin
        xyz="0 0 0"
        rpy="0 0 0" />
      <geometry>
        <mesh
          filename="package://robot/meshes/left_Link.STL" />
      </geometry>
    </collision>
  </link>

  <joint
    name="right_Joint"
    type="continuous">
    <origin
      xyz="0 -0.165 0.02"
      rpy="1.5707963267949 0 0" />
    <parent
      link="base_Link" />
    <child
      link="right_Link" />
    <axis
      xyz="0 0 -1" />
  </joint>

  <link
    name="right_Link">
    <inertial>
      <origin
        xyz="0 -2.77555756156289E-17 -0.0200584795321637"
        rpy="0 0 0" />
      <mass
        value="0.201454628911446" />
      <inertia
        ixx="0.000107599473032008"
        ixy="1.56972532318077E-37"
        ixz="3.0241735233884E-21"
        iyy="0.000107599473032008"
        iyz="2.92438498234608E-37"
        izz="0.000160850771048428" />
    </inertial>
    <visual>
      <origin
        xyz="0 0 0"
        rpy="0 0 0" />
      <geometry>
        <mesh
          filename="package://robot/meshes/right_Link.STL" />
      </geometry>
      <material
        name="">
        <color
          rgba="0.792156862745098 0.819607843137255 0.933333333333333 1" />
      </material>
    </visual>
    <collision>
      <origin
        xyz="0 0 0"
        rpy="0 0 0" />
      <geometry>
        <mesh
          filename="package://robot/meshes/right_Link.STL" />
      </geometry>
    </collision>
  </link>

  <joint
    name="banh_phu1_Joint"
    type="continuous">
    <origin
      xyz="0.125000000000002 0.0794032737073749 -0.00999999999999938"
      rpy="0 0 0" />
    <parent
      link="base_Link" />
    <child
      link="banh_phu1_Link" />
    <axis
      xyz="0 1 0" />
  </joint>

  <link
    name="banh_phu1_Link">
    <inertial>
      <origin
        xyz="0 -0.00499999999999995 0"
        rpy="0 0 0" />
      <mass
        value="0.00392699081698724" />
      <inertia
        ixx="3.08841465294309E-07"
        ixy="-5.11985520817712E-24"
        ixz="1.15783744595645E-24"
        iyy="1.59534001940107E-07"
        iyz="1.75129487965311E-24"
        izz="3.08841465294309E-07" />
    </inertial>
    <visual>
      <origin
        xyz="0 0 0"
        rpy="0 0 0" />
      <geometry>
        <mesh
          filename="package://robot/meshes/banh_phu1_Link.STL" />
      </geometry>
      <material
        name="">
        <color
          rgba="0.792156862745098 0.819607843137255 0.933333333333333 1" />
      </material>
    </visual>
    <collision>
      <origin
        xyz="0 0 0"
        rpy="0 0 0" />
      <geometry>
        <mesh
          filename="package://robot/meshes/banh_phu1_Link.STL" />
      </geometry>
    </collision>
  </link>
  
  <joint
    name="banh_phu2_Joint"
    type="continuous">
    <origin
      xyz="0.125 -0.0709613882893278 -0.00999999999999998"
      rpy="0 0 0" />
    <parent
      link="base_Link" />
    <child
      link="banh_phu2_Link" />
    <axis
      xyz="0 1 0" />
  </joint>
  
  <link
    name="banh_phu2_Link">
    <inertial>
      <origin
        xyz="0 -0.005 0"
        rpy="0 0 0" />
      <mass
        value="0.00392699081698724" />
      <inertia
        ixx="3.08841465294309E-07"
        ixy="-2.34057621937935E-25"
        ixz="-5.22911702336582E-24"
        iyy="1.59534001940107E-07"
        iyz="1.0610482833426E-24"
        izz="3.08841465294309E-07" />
    </inertial>
    <visual>
      <origin
        xyz="0 0 0"
        rpy="0 0 0" />
      <geometry>
        <mesh
          filename="package://robot/meshes/banh_phu2_Link.STL" />
      </geometry>
      <material
        name="">
        <color
          rgba="0.792156862745098 0.819607843137255 0.933333333333333 1" />
      </material>
    </visual>
    <collision>
      <origin
        xyz="0 0 0"
        rpy="0 0 0" />
      <geometry>
        <mesh
          filename="package://robot/meshes/banh_phu2_Link.STL" />
      </geometry>
    </collision>
  </link>
  
  <joint
    name="banh_phu3_Joint"
    type="continuous">
    <origin
      xyz="-0.125 0.0800786890374973 -0.00999999999999998"
      rpy="0 0 0" />
    <parent
      link="base_Link" />
    <child
      link="banh_phu3_Link" />
    <axis
      xyz="0 1 0" />
  </joint>
  
  <link
    name="banh_phu3_Link">
    <inertial>
      <origin
        xyz="0 -0.005 0"
        rpy="0 0 0" />
      <mass
        value="0.00392699081698724" />
      <inertia
        ixx="3.0884146529431E-07"
        ixy="1.91412275456591E-24"
        ixz="-8.22333851151351E-24"
        iyy="1.59534001940107E-07"
        iyz="-2.48566878310362E-24"
        izz="3.0884146529431E-07" />
    </inertial>
    <visual>
      <origin
        xyz="0 0 0"
        rpy="0 0 0" />
      <geometry>
        <mesh
          filename="package://robot/meshes/banh_phu3_Link.STL" />
      </geometry>
      <material
        name="">
        <color
          rgba="0.792156862745098 0.819607843137255 0.933333333333333 1" />
      </material>
    </visual>
    <collision>
      <origin
        xyz="0 0 0"
        rpy="0 0 0" />
      <geometry>
        <mesh
          filename="package://robot/meshes/banh_phu3_Link.STL" />
      </geometry>
    </collision>
  </link>
  
  <joint
    name="banh_phu4_Joint"
    type="continuous">
    <origin
      xyz="-0.125 -0.0695542726566803 -0.00999999999999997"
      rpy="0 0 0" />
    <parent
      link="base_Link" />
    <child
      link="banh_phu4_Link" />
    <axis
      xyz="0 1 0" />
  </joint>
  
  <link
    name="banh_phu4_Link">
    <inertial>
      <origin
        xyz="0 -0.00499999999999998 0"
        rpy="0 0 0" />
      <mass
        value="0.00392699081698724" />
      <inertia
        ixx="3.08841465294309E-07"
        ixy="1.98857827620359E-25"
        ixz="9.64182401507123E-24"
        iyy="1.59534001940107E-07"
        iyz="-4.13224958127416E-25"
        izz="3.08841465294309E-07" />
    </inertial>
    <visual>
      <origin
        xyz="0 0 0"
        rpy="0 0 0" />
      <geometry>
        <mesh
          filename="package://robot/meshes/banh_phu4_Link.STL" />
      </geometry>
      <material
        name="">
        <color
          rgba="0.792156862745098 0.819607843137255 0.933333333333333 1" />
      </material>
    </visual>
    <collision>
      <origin
        xyz="0 0 0"
        rpy="0 0 0" />
      <geometry>
        <mesh
          filename="package://robot/meshes/banh_phu4_Link.STL" />
      </geometry>
    </collision>
  </link>
  
  <joint name="imu_joint" type="fixed">
    <parent link="base_Link"/>
    <child link="imu_link"/>
    <origin xyz="-0.032 0 0.068" rpy="0 0 0"/>
  </joint>

  <link name="imu_link"/>

  <joint name="scan_joint" type="fixed">
    <parent link="base_Link"/>
    <child link="base_scan"/>
    <origin xyz="0.0875 0 0.15" rpy="0 0 0"/>
  </joint>

  <link name="base_scan">
    <visual>
      <origin xyz="0 0 0.0" rpy="0 0 0"/>
      <geometry>
        <mesh filename="package://turtlebot3_description/meshes/sensors/lds.stl" scale="0.001 0.001 0.001"/>
      </geometry>
      <material name="dark"/>
    </visual>

    <collision>
      <origin xyz="0.015 0 -0.0065" rpy="0 0 0"/>
      <geometry>
        <cylinder length="0.0315" radius="0.055"/>
      </geometry>
    </collision>

    <inertial>
      <mass value="0.114" />
      <origin xyz="0 0 0" />
      <inertia ixx="0.001" ixy="0.0" ixz="0.0"
               iyy="0.001" iyz="0.0"
               izz="0.001" />
    </inertial>
  </link>

</robot>
